<?xml version="1.0"?>
<robot xmlns:xacro="http://ros.org/wiki/xacro">

    <xacro:property name="mass" value="0.1" />
    <xacro:property name="radius" value="0.05" />
    <xacro:property name="length" value="0.02" />

    <xacro:macro name="tinyquad_wheel" params="pose_prefix y_mirror">

        <link name="${pose_prefix}_wheel" >
            <visual>
                <geometry>
                    <cylinder length="${length}" radius="${radius}"/>
                </geometry>
                <material name="blue">
                    <color rgba="0 0 .8 1"/>
                </material>
            </visual>
            <collision>
                <geometry>
                    <cylinder length="${length}" radius="${radius}"/>
                </geometry>
            </collision>
            <surface>
                <friction>
                  <ode>
                    <mu>150.0</mu>
                    <mu2>150.0</mu2>
                    <kp value="10000000.0" />
                    <kd value="1.0" />
                  </ode>
                </friction>
            </surface>
            <inertial>
                <origin xyz="0 0 0"
                rpy="0 0 0" />
                <mass value="${mass}"/>
                <inertia    ixx="${ (1/12) * mass * (3* (radius * radius) + (length * length) ) }" 
                            ixy="0.00"  
                            ixz="0.00" 
                            iyy="${ (1/12) * mass * (3* (radius * radius) + (length * length) ) }" 
                            iyz="0.00" 
                            izz="${ mass * radius * radius / 2 }" />
            </inertial>
        </link>

        <joint name="${pose_prefix}_wheel_joint" type="continuous">
            <origin xyz="0 ${y_mirror*0.06} -0.085"
                    rpy="1.5707964 0 0" />
            <parent link="${pose_prefix}L_L" />
            <child link="${pose_prefix}_wheel" />
            <axis xyz="0 0 -1" />
        </joint>

    </xacro:macro>

</robot>